<?xml version="1.0" ?>
<!-- =================================================================================== -->
<!-- |    This document was autogenerated by xacro from /home/max-dev/Projects/OpenArm/OpenArm_ws/src/OpenArm/arm_description/urdf/OpenArmVKillian.urdf | -->
<!-- |    EDITING THIS FILE BY HAND IS NOT RECOMMENDED                                 | -->
<!-- =================================================================================== -->
<robot name="OpenArmVKillian">
  <link name="Cycloidal_Simplified_for_FEA">
    <inertial>
      <origin rpy=" -0.0 0.0" xyz="-0.010005039449546161 4.037251654477103e-05 -0.031015874921037394"/>
      <mass value="0.43211727572229136"/>
      <inertia ixx="0.0004211761261660727" ixy="4.2155668701638026e-07" ixz="-1.0981594307291016e-05" iyy="0.00041859561398810397" iyz="6.3117373221706e-07" izz="0.00039046053891583755"/>
    </inertial>
    <visual name="Cycloidal_Simplified_for_FEA_visual">
      <origin rpy="1.7093819330601059 0.28036860475382164 0.46689412820105575" xyz="-0.005295984244864869 -4.0202369612032386e-05 -0.016150322575823637"/>
      <geometry>
        <mesh filename="package://arm_description/meshes_2/Cycloidal_Simplified_for_FEA.stl" scale="0.001 0.001 0.001"/>
      </geometry>
    </visual>
    <collision name="Cycloidal_Simplified_for_FEA_collision">
      <origin rpy="1.7093819330601059 0.28036860475382164 0.46689412820105575" xyz="-0.005295984244864869 -4.0202369612032386e-05 -0.016150322575823637"/>
      <geometry>
        <mesh filename="package://arm_description/meshes_2/Cycloidal_Simplified_for_FEA.stl" scale="0.001 0.001 0.001"/>
      </geometry>
    </collision>
  </link>
  <link name="Base_not_rotational">
    <inertial>
      <origin rpy="0.0 -0.0 0.0" xyz="0.0042873277363599275 -0.013295262343984931 -0.026340207701857993"/>
      <mass value="0.37248647313058036"/>
      <inertia ixx="0.000888141254014374" ixy="-2.2479878287809488e-05" ixz="4.908688801431602e-05" iyy="0.0009506048102522759" iyz="-0.00015222368011418719" izz="0.0009757840198543197"/>
    </inertial>
    <visual name="Base_not_rotational_visual">
      <origin rpy="-1.5707963267948901 -1.2127115078218577e-16 0.31193908652251523" xyz="3.1378266385218014e-09 2.6039605671712706e-09 -3.5229662387337156e-09"/>
      <geometry>
        <mesh filename="package://arm_description/meshes_2/Base_not_rotational.stl" scale="0.001 0.001 0.001"/>
      </geometry>
    </visual>
    <collision name="Base_not_rotational_collision">
      <origin rpy="-1.5707963267948901 -1.2127115078218577e-16 0.31193908652251523" xyz="3.1378266385218014e-09 2.6039605671712706e-09 -3.5229662387337156e-09"/>
      <geometry>
        <mesh filename="package://arm_description/meshes_2/Base_not_rotational.stl" scale="0.001 0.001 0.001"/>
      </geometry>
    </collision>
  </link>
  <link name="Primary-Joint-Cable-SpoolV2">
    <inertial>
      <origin rpy="0.0 -3.6529045210900597e-34 0.0" xyz="0.002521548338999793 -0.00893759411510601 0.0007672425978599407"/>
      <mass value="0.06709387547157461"/>
      <inertia ixx="1.984485917520644e-05" ixy="-3.4232425893190895e-06" ixz="1.1617074769923288e-06" iyy="3.123111170949197e-05" iyz="6.559807134067732e-07" izz="1.6844925871048466e-05"/>
    </inertial>
    <visual name="Primary-Joint-Cable-SpoolV2_visual">
      <origin rpy="-1.5707963267947909 -0.44730759934178205 0.3119390865224753" xyz="-4.917289615491427e-09 -3.3980683156187295e-10 -3.52296254391149e-09"/>
      <geometry>
        <mesh filename="package://arm_description/meshes_2/Primary-Joint-Cable-SpoolV2.stl" scale="0.001 0.001 0.001"/>
      </geometry>
    </visual>
    <collision name="Primary-Joint-Cable-SpoolV2_collision">
      <origin rpy="-1.5707963267947909 -0.44730759934178205 0.3119390865224753" xyz="-4.917289615491427e-09 -3.3980683156187295e-10 -3.52296254391149e-09"/>
      <geometry>
        <mesh filename="package://arm_description/meshes_2/Primary-Joint-Cable-SpoolV2.stl" scale="0.001 0.001 0.001"/>
      </geometry>
    </collision>
  </link>
  <link name="Primary-Joint-Cap">
    <inertial>
      <origin rpy="0.0 0.0 0.0" xyz="0.0005981956225197394 3.523006739669654e-09 -0.0018550580640503966"/>
      <mass value="0.01500275606707962"/>
      <inertia ixx="3.849957308827475e-06" ixy="-1.7629125141943348e-15" ixz="-1.0170733852638695e-06" iyy="3.5219848121157893e-06" iyz="-5.687725302595386e-16" izz="6.676024531091729e-06"/>
    </inertial>
    <visual name="Primary-Joint-Cap_visual">
      <origin rpy="3.003007047324583 0.28036860475382347 2.6746985253887368" xyz="-0.002148330649274541 3.522963680779867e-09 0.006662176845537573"/>
      <geometry>
        <mesh filename="package://arm_description/meshes_2/Primary-Joint-Cap.stl" scale="0.001 0.001 0.001"/>
      </geometry>
    </visual>
    <collision name="Primary-Joint-Cap_collision">
      <origin rpy="3.003007047324583 0.28036860475382347 2.6746985253887368" xyz="-0.002148330649274541 3.522963680779867e-09 0.006662176845537573"/>
      <geometry>
        <mesh filename="package://arm_description/meshes_2/Primary-Joint-Cap.stl" scale="0.001 0.001 0.001"/>
      </geometry>
    </collision>
  </link>
  <link name="Primary-Segment-Inner">
    <inertial>
      <origin rpy="0.0 -0.0 0.0" xyz="-0.13304433589921863 -0.029927241951823336 -0.0651525796956157"/>
      <mass value="0.8117447798010718"/>
      <inertia ixx="0.0036186830426251093" ixy="-0.002750233123022108" ixz="-0.004000748566730466" iyy="0.01113380439085149" iyz="-0.0013087708358059684" izz="0.009474738555957474"/>
    </inertial>
    <visual name="Primary-Segment-Inner_visual">
      <origin rpy="1.5707963267947909 0.4473075993417821 -2.829653567067367" xyz="-2.0652339571824998e-09 9.760454844354172e-10 -3.5229663097879893e-09"/>
      <geometry>
        <mesh filename="package://arm_description/meshes_2/Primary-Segment-Inner.stl" scale="0.001 0.001 0.001"/>
      </geometry>
    </visual>
    <collision name="Primary-Segment-Inner_collision">
      <origin rpy="1.5707963267947909 0.4473075993417821 -2.829653567067367" xyz="-2.0652339571824998e-09 9.760454844354172e-10 -3.5229663097879893e-09"/>
      <geometry>
        <mesh filename="package://arm_description/meshes_2/Primary-Segment-Inner.stl" scale="0.001 0.001 0.001"/>
      </geometry>
    </collision>
  </link>
  <link name="Primary-Segment-Outer">
    <inertial>
      <origin rpy="0.0 -0.0 1.5407439555097883e-33" xyz="-0.11766063510716138 -0.009065294960777485 0.027966307534680795"/>
      <mass value="0.6087783987110288"/>
      <inertia ixx="0.0024773658895871353" ixy="-0.002812162730520165" ixz="0.0019150536246483603" iyy="0.0066016594434582555" iyz="0.0009051500026528514" izz="0.007809991091397961"/>
    </inertial>
    <visual name="Primary-Segment-Outer_visual">
      <origin rpy="-0.13858560626520178 -0.28036860475377723 -2.6746985253887434" xyz="0.0330208571358213 0.06836625647703994 -0.030664102133202677"/>
      <geometry>
        <mesh filename="package://arm_description/meshes_2/Primary-Segment-Outer.stl" scale="0.001 0.001 0.001"/>
      </geometry>
    </visual>
    <collision name="Primary-Segment-Outer_collision">
      <origin rpy="-0.13858560626520178 -0.28036860475377723 -2.6746985253887434" xyz="0.0330208571358213 0.06836625647703994 -0.030664102133202677"/>
      <geometry>
        <mesh filename="package://arm_description/meshes_2/Primary-Segment-Outer.stl" scale="0.001 0.001 0.001"/>
      </geometry>
    </collision>
  </link>
  <link name="Secondary-Joint-Cable-SpoolV2">
    <inertial>
      <origin rpy="0.0 -0.0 3.0814879110195774e-33" xyz="-0.004636774491303441 0.00014436756459744517 -0.009939085089860775"/>
      <mass value="0.07280814538663145"/>
      <inertia ixx="2.1178807136042192e-05" ixy="1.694971728249967e-08" ixz="4.62666642121745e-06" iyy="2.106458434528862e-05" iyz="-4.485216821680654e-07" izz="3.3418820381075895e-05"/>
    </inertial>
    <visual name="Secondary-Joint-Cable-SpoolV2_visual">
      <origin rpy="2.8312797622258192 -0.03233709051087522 -1.6712806537466753" xyz="-0.0027621473841014676 6.034188970716059e-10 -0.008565658793609678"/>
      <geometry>
        <mesh filename="package://arm_description/meshes_2/Secondary-Joint-Cable-SpoolV2.stl" scale="0.001 0.001 0.001"/>
      </geometry>
    </visual>
    <collision name="Secondary-Joint-Cable-SpoolV2_collision">
      <origin rpy="2.8312797622258192 -0.03233709051087522 -1.6712806537466753" xyz="-0.0027621473841014676 6.034188970716059e-10 -0.008565658793609678"/>
      <geometry>
        <mesh filename="package://arm_description/meshes_2/Secondary-Joint-Cable-SpoolV2.stl" scale="0.001 0.001 0.001"/>
      </geometry>
    </collision>
  </link>
  <link name="Secondary-Joint-Cartilage">
    <inertial>
      <origin rpy="0.0 -0.0 -1.5407439555097883e-33" xyz="-0.00018414114440503228 -6.011204334299692e-10 0.0005710414464700974"/>
      <mass value="0.003925813316644754"/>
      <inertia ixx="1.0416476417322547e-06" ixy="-5.898064477145328e-17" ixz="-2.778157640640713e-07" iyy="9.520612555759434e-07" iyz="-1.9081836919252125e-17" izz="1.813593929998747e-06"/>
    </inertial>
    <visual name="Secondary-Joint-Cartilage_visual">
      <origin rpy="1.287855554242624 -0.13314145327126095 1.142478462503465" xyz="1.6869586261236691e-09 -6.011444497744378e-10 -2.7003850178175528e-09"/>
      <geometry>
        <mesh filename="package://arm_description/meshes_2/Secondary-Joint-Cartilage.stl" scale="0.001 0.001 0.001"/>
      </geometry>
    </visual>
    <collision name="Secondary-Joint-Cartilage_collision">
      <origin rpy="1.287855554242624 -0.13314145327126095 1.142478462503465" xyz="1.6869586261236691e-09 -6.011444497744378e-10 -2.7003850178175528e-09"/>
      <geometry>
        <mesh filename="package://arm_description/meshes_2/Secondary-Joint-Cartilage.stl" scale="0.001 0.001 0.001"/>
      </geometry>
    </collision>
  </link>
  <link name="SecondarySegmentFinney">
    <inertial>
      <origin rpy="0.0 7.703719777548943e-34 0.0" xyz="0.13644338439213144 0.0584008456375981 -0.047391241374654454"/>
      <mass value="0.4844233890141828"/>
      <inertia ixx="0.0006798140859433921" ixy="-0.0012488762538693657" ixz="0.00045737323871009023" iyy="0.003808991267500894" iyz="0.00016887134017853905" izz="0.004073043227087847"/>
    </inertial>
    <visual name="SecondarySegmentFinney_visual">
      <origin rpy="1.5707963267939995 1.4652536089066597 -2.829653567068198" xyz="-0.0031833500194353805 -0.0010265281123399816 -0.03157332765306819"/>
      <geometry>
        <mesh filename="package://arm_description/meshes_2/SecondarySegmentFinney.stl" scale="0.001 0.001 0.001"/>
      </geometry>
    </visual>
    <collision name="SecondarySegmentFinney_collision">
      <origin rpy="1.5707963267939995 1.4652536089066597 -2.829653567068198" xyz="-0.0031833500194353805 -0.0010265281123399816 -0.03157332765306819"/>
      <geometry>
        <mesh filename="package://arm_description/meshes_2/SecondarySegmentFinney.stl" scale="0.001 0.001 0.001"/>
      </geometry>
    </collision>
  </link>
  <link name="Wrist-mount">
    <inertial>
      <origin rpy="0.0 -3.0814879110195774e-33 0.0" xyz="-0.010403968531903587 -0.0033548998902476514 -0.0015498023688390818"/>
      <mass value="0.15179021016003724"/>
      <inertia ixx="7.758604023656854e-05" ixy="-2.4029221062048932e-05" ixz="4.163331526325226e-06" iyy="0.00014435431114835634" iyz="1.34257013009037e-06" izz="0.00015027078661643262"/>
    </inertial>
    <visual name="Wrist-mount_visual">
      <origin rpy="-1.6763390446831419 1.0731952839652978e-13 -1.2588572402724203" xyz="0.012303771163042257 0.003967559208186486 -0.0013695097040198334"/>
      <geometry>
        <mesh filename="package://arm_description/meshes_2/Wrist-mount.stl" scale="0.001 0.001 0.001"/>
      </geometry>
    </visual>
    <collision name="Wrist-mount_collision">
      <origin rpy="-1.6763390446831419 1.0731952839652978e-13 -1.2588572402724203" xyz="0.012303771163042257 0.003967559208186486 -0.0013695097040198334"/>
      <geometry>
        <mesh filename="package://arm_description/meshes_2/Wrist-mount.stl" scale="0.001 0.001 0.001"/>
      </geometry>
    </collision>
  </link>
  <link name="L1-v1">
    <inertial>
      <origin rpy="0.0 -2.1322238035672327e-31 0.0" xyz="-0.014693983518820418 0.010883931851679947 0.000725938309549079"/>
      <mass value="0.0477955977122399"/>
      <inertia ixx="3.3360118559981066e-06" ixy="2.3828997924904763e-06" ixz="-7.557961533618566e-07" iyy="5.0472541674086835e-06" iyz="5.468214624804426e-07" izz="6.6214176666776765e-06"/>
    </inertial>
    <visual name="L1-v1_visual">
      <origin rpy="2.955998194065042 -0.16717707021131 -0.5427289272796788" xyz="0.013314564411278944 0.003356309919170073 0.0039022864026089367"/>
      <geometry>
        <mesh filename="package://arm_description/meshes_2/L1-v1.stl" scale="0.001 0.001 0.001"/>
      </geometry>
    </visual>
    <collision name="L1-v1_collision">
      <origin rpy="2.955998194065042 -0.16717707021131 -0.5427289272796788" xyz="0.013314564411278944 0.003356309919170073 0.0039022864026089367"/>
      <geometry>
        <mesh filename="package://arm_description/meshes_2/L1-v1.stl" scale="0.001 0.001 0.001"/>
      </geometry>
    </collision>
  </link>
  <link name="L1-v1-1">
    <inertial>
      <origin rpy="0.0 -2.1322238035672327e-31 0.0" xyz="-0.010171133533156542 -0.01349007349112057 0.007033207081008684"/>
      <mass value="0.0477955977122399"/>
      <inertia ixx="5.15216610208743e-06" ixy="-2.342356233839931e-06" ixz="5.103200177288519e-07" iyy="3.2317351842513905e-06" iyz="7.829500594822636e-07" izz="6.620782403742174e-06"/>
    </inertial>
    <visual name="L1-v1-1_visual">
      <origin rpy="-0.18526230476825428 0.167545875828908 0.9096059558315942" xyz="0.013272732433441696 0.003581740878057147 0.0038439534058873903"/>
      <geometry>
        <mesh filename="package://arm_description/meshes_2/L1-v1-1.stl" scale="0.001 0.001 0.001"/>
      </geometry>
    </visual>
    <collision name="L1-v1-1_collision">
      <origin rpy="-0.18526230476825428 0.167545875828908 0.9096059558315942" xyz="0.013272732433441696 0.003581740878057147 0.0038439534058873903"/>
      <geometry>
        <mesh filename="package://arm_description/meshes_2/L1-v1-1.stl" scale="0.001 0.001 0.001"/>
      </geometry>
    </collision>
  </link>
  <link name="L2-v1">
    <inertial>
      <origin rpy="0.0 -0.0 7.703719777548945e-34" xyz="0.022688529357825546 -0.00494056739565643 0.005713691263422121"/>
      <mass value="0.011794440016492293"/>
      <inertia ixx="1.185065367679053e-06" ixy="-7.343654224349985e-08" ixz="-6.401190208507861e-07" iyy="2.446755992202565e-06" iyz="-2.105113608660313e-07" izz="2.747995916036263e-06"/>
    </inertial>
    <visual name="L2-v1_visual">
      <origin rpy="0.8994172111729665 -1.170385538863733 -2.318894891133177" xyz="0.0118989571622674 -0.005973133409869007 0.0015729017466268402"/>
      <geometry>
        <mesh filename="package://arm_description/meshes_2/L2-v1.stl" scale="0.001 0.001 0.001"/>
      </geometry>
    </visual>
    <collision name="L2-v1_collision">
      <origin rpy="0.8994172111729665 -1.170385538863733 -2.318894891133177" xyz="0.0118989571622674 -0.005973133409869007 0.0015729017466268402"/>
      <geometry>
        <mesh filename="package://arm_description/meshes_2/L2-v1.stl" scale="0.001 0.001 0.001"/>
      </geometry>
    </collision>
  </link>
  <link name="L2-v1-1">
    <inertial>
      <origin rpy="0.0 -0.0 0.0" xyz="0.023645138008599426 0.0034900971639209646 -0.0007426990282474577"/>
      <mass value="0.011794440016492293"/>
      <inertia ixx="9.99621746550737e-07" ixy="2.2649148307589716e-07" ixz="1.7977188778882039e-07" iyy="2.408958295107514e-06" iyz="-1.7831145757369118e-07" izz="2.971237234260497e-06"/>
    </inertial>
    <visual name="L2-v1-1_visual">
      <origin rpy="-0.5256131287609266 -1.2866712945260153 -1.218285923428689" xyz="0.012250841721346788 0.005439585328676415 0.0002556529002101371"/>
      <geometry>
        <mesh filename="package://arm_description/meshes_2/L2-v1-1.stl" scale="0.001 0.001 0.001"/>
      </geometry>
    </visual>
    <collision name="L2-v1-1_collision">
      <origin rpy="-0.5256131287609266 -1.2866712945260153 -1.218285923428689" xyz="0.012250841721346788 0.005439585328676415 0.0002556529002101371"/>
      <geometry>
        <mesh filename="package://arm_description/meshes_2/L2-v1-1.stl" scale="0.001 0.001 0.001"/>
      </geometry>
    </collision>
  </link>
  <link name="L3-v1">
    <inertial>
      <origin rpy="-3.0814879110195774e-33 -0.0 0.0" xyz="0.0214880058838353 0.0008541909186375562 0.01661172645326701"/>
      <mass value="0.008581820338431405"/>
      <inertia ixx="6.39560467244858e-07" ixy="4.748825985855616e-07" ixz="-4.638871221006312e-07" iyy="2.3683501541422146e-06" iyz="9.513601185897992e-08" izz="2.463115679389536e-06"/>
    </inertial>
    <visual name="L3-v1_visual">
      <origin rpy="-2.2421754424168214 1.1703855388637283 2.3188948911331653" xyz="0.004146701071010597 0.005660630056076101 0.010905395959864067"/>
      <geometry>
        <mesh filename="package://arm_description/meshes_2/L3-v1.stl" scale="0.001 0.001 0.001"/>
      </geometry>
    </visual>
    <collision name="L3-v1_collision">
      <origin rpy="-2.2421754424168214 1.1703855388637283 2.3188948911331653" xyz="0.004146701071010597 0.005660630056076101 0.010905395959864067"/>
      <geometry>
        <mesh filename="package://arm_description/meshes_2/L3-v1.stl" scale="0.001 0.001 0.001"/>
      </geometry>
    </collision>
  </link>
  <link name="L3-v1-1">
    <inertial>
      <origin rpy="0.0 -0.0 0.0" xyz="0.014457862820827465 -0.011513755092237262 0.019920274855670925"/>
      <mass value="0.008581820338431405"/>
      <inertia ixx="1.2508260646593335e-06" ixy="2.9622325357610584e-08" ixz="-1.053524820516464e-06" iyy="2.4929402143904897e-06" iyz="-1.1002408976294965e-08" izz="1.7272600217276522e-06"/>
    </inertial>
    <visual name="L3-v1-1_visual">
      <origin rpy="2.6159795248288975 1.2866712945260264 1.2182859234286552" xyz="0.0006992338190756797 -0.010887907255705187 0.007009296582480431"/>
      <geometry>
        <mesh filename="package://arm_description/meshes_2/L3-v1-1.stl" scale="0.001 0.001 0.001"/>
      </geometry>
    </visual>
    <collision name="L3-v1-1_collision">
      <origin rpy="2.6159795248288975 1.2866712945260264 1.2182859234286552" xyz="0.0006992338190756797 -0.010887907255705187 0.007009296582480431"/>
      <geometry>
        <mesh filename="package://arm_description/meshes_2/L3-v1-1.stl" scale="0.001 0.001 0.001"/>
      </geometry>
    </collision>
  </link>
  <link name="Openhand1.0_Hand_simplifiedmain-v1">
    <inertial>
      <origin rpy="0.0 -0.0 -4.8148248609680905e-34" xyz="0.07526513593535683 0.008681592743399946 0.024185486744490135"/>
      <mass value="2.854965155689975"/>
      <inertia ixx="0.0020639890810565387" ixy="-0.0002485289175321869" ixz="-0.0006854823261955297" iyy="0.004236967092320909" iyz="-4.318434733330268e-05" izz="0.003954860299096861"/>
    </inertial>
    <visual name="Openhand1.0_Hand_simplifiedmain-v1_visual">
      <origin rpy="2.256654547549486 -1.0679895336171166 -2.0820594279662163" xyz="0.06808720554455291 0.007578654414583568 0.02195586840731039"/>
      <geometry>
        <mesh filename="package://arm_description/meshes_2/Openhand1.0_Hand_simplifiedmain-v1.stl" scale="0.001 0.001 0.001"/>
      </geometry>
    </visual>
    <collision name="Openhand1.0_Hand_simplifiedmain-v1_collision">
      <origin rpy="2.256654547549486 -1.0679895336171166 -2.0820594279662163" xyz="0.06808720554455291 0.007578654414583568 0.02195586840731039"/>
      <geometry>
        <mesh filename="package://arm_description/meshes_2/Openhand1.0_Hand_simplifiedmain-v1.stl" scale="0.001 0.001 0.001"/>
      </geometry>
    </collision>
  </link>
  <link name="base_link">
    <inertial>
      <origin rpy="1.5707963267948966 0.0 0.0" xyz="0.0 -0.012976976768062611 0.0"/>
      <mass value="0.8794243359130697"/>
      <inertia ixx="0.003804908276428237" ixy="-3.469446951953614e-18" ixz="0.0" iyy="0.0050497068127919875" iyz="0.0" izz="0.0029501665826188184"/>
    </inertial>
    <visual name="base_link_visual">
      <origin rpy="1.5707963267948966 0.0 0.0" xyz="0.0 0.0 0.0"/>
      <geometry>
        <mesh filename="package://arm_description/meshes_2/base_link.stl" scale="0.001 0.001 0.001"/>
      </geometry>
    </visual>
    <collision name="base_link_collision">
      <origin rpy="1.5707963267948966 0.0 0.0" xyz="0.0 0.0 0.0"/>
      <geometry>
        <mesh filename="package://arm_description/meshes_2/base_link.stl" scale="0.001 0.001 0.001"/>
      </geometry>
    </collision>
  </link>
  <link name="Cycloidal_Simplified_for_FEA-1">
    <inertial>
      <origin rpy="0.0 -0.0 0.0" xyz="4.001155802363599e-05 -6.3475935993295705e-06 0.037669646861678584"/>
      <mass value="0.43211727572229136"/>
      <inertia ixx="0.000418662603423825" ixy="6.688693065803886e-07" ixz="-7.324609151600214e-07" iyy="0.0004246313262313145" iyz="-3.1381741545655206e-09" izz="0.00038693834941444516"/>
    </inertial>
    <visual name="Cycloidal_Simplified_for_FEA-1_visual">
      <origin rpy="-1.5707963267948888 -5.501788011386564e-15 1.0471975511965952" xyz="-4.6465262986004064e-05 -8.048302704466437e-05 0.022076271170119136"/>
      <geometry>
        <mesh filename="package://arm_description/meshes_2/Cycloidal_Simplified_for_FEA-1.stl" scale="0.001 0.001 0.001"/>
      </geometry>
    </visual>
    <collision name="Cycloidal_Simplified_for_FEA-1_collision">
      <origin rpy="-1.5707963267948888 -5.501788011386564e-15 1.0471975511965952" xyz="-4.6465262986004064e-05 -8.048302704466437e-05 0.022076271170119136"/>
      <geometry>
        <mesh filename="package://arm_description/meshes_2/Cycloidal_Simplified_for_FEA-1.stl" scale="0.001 0.001 0.001"/>
      </geometry>
    </collision>
  </link>
  <link name="Cycloidal_Simplified_for_FEA-2">
    <inertial>
      <origin rpy="0.0 -0.0 0.0" xyz="0.011524990419070989 -1.4508300662470219e-05 0.035863329850015474"/>
      <mass value="0.43211727572229136"/>
      <inertia ixx="0.00041687106474162794" ixy="-2.0282770086463286e-06" ixz="-9.019549015498778e-06" iyy="0.0004237184033407393" iyz="1.0417085826684715e-06" izz="0.0003896428109874256"/>
    </inertial>
    <visual name="Cycloidal_Simplified_for_FEA-2_visual">
      <origin rpy="-1.882735413317379 8.640893553184528e-14 -1.570796326794924" xyz="0.006775307893589613 9.293327852802236e-05 0.021010878470682785"/>
      <geometry>
        <mesh filename="package://arm_description/meshes_2/Cycloidal_Simplified_for_FEA-2.stl" scale="0.001 0.001 0.001"/>
      </geometry>
    </visual>
    <collision name="Cycloidal_Simplified_for_FEA-2_collision">
      <origin rpy="-1.882735413317379 8.640893553184528e-14 -1.570796326794924" xyz="0.006775307893589613 9.293327852802236e-05 0.021010878470682785"/>
      <geometry>
        <mesh filename="package://arm_description/meshes_2/Cycloidal_Simplified_for_FEA-2.stl" scale="0.001 0.001 0.001"/>
      </geometry>
    </collision>
  </link>
  <joint name="Primary-Segment-Inner_Rigid-6" type="fixed">
    <origin rpy="1.5707963267948974 -5.551115123125788e-17 5.551115123125463e-17" xyz="-0.05453487999999993 0.03605289000000006 -0.06836626000000003"/>
    <parent link="Primary-Segment-Inner"/>
    <child link="Primary-Segment-Outer"/>
  </joint>
  <joint name="Primary-Segment-Outer_Rigid-7" type="fixed">
    <origin rpy="-2.7755575615628898e-17 -1.6653345369377353e-16 -5.5511151231257815e-17" xyz="0.03886738999999999 0.06836626 -0.01253344999999996"/>
    <parent link="Primary-Segment-Outer"/>
    <child link="Cycloidal_Simplified_for_FEA"/>
  </joint>
  <joint name="Cycloidal_Simplified_for_FEA_Rigid-8" type="fixed">
    <origin rpy="-1.5707963267948974 1.0408340855860847e-16 5.551115123125783e-17" xyz="0.0020194400000001166 0.0 0.006262449999999902"/>
    <parent link="Cycloidal_Simplified_for_FEA"/>
    <child link="Primary-Joint-Cable-SpoolV2"/>
  </joint>
  <joint name="Primary-Joint-Cable-SpoolV2_Rigid-9" type="fixed">
    <origin rpy="-1.570796326794896 4.1633363423443364e-17 6.938893903907262e-18" xyz="0.005677729999999955 -0.01760719000000002 -3.552713678800501e-17"/>
    <parent link="Primary-Joint-Cable-SpoolV2"/>
    <child link="Primary-Joint-Cap"/>
  </joint>
  <joint name="Primary-Segment-Inner_Rigid-10" type="fixed">
    <origin rpy="-1.570796326794896 -5.551115123125788e-17 5.551115123125463e-17" xyz="-0.32396368999999986 -0.08539722999999988 -0.16049088000000009"/>
    <parent link="Primary-Segment-Inner"/>
    <child link="Secondary-Joint-Cartilage"/>
  </joint>
  <joint name="Secondary-Joint-Cartilage_Revolute-11" type="continuous">
    <origin rpy="1.5707963267948966 1.3877787807814457e-17 8.326672684688672e-17" xyz="-0.0003682799999999986 0.0 0.001142089999999989"/>
    <parent link="Secondary-Joint-Cartilage"/>
    <child link="SecondarySegmentFinney"/>
    <axis xyz="0.30690499999999993 -0.95174 -4.4313858138522735e-17"/>
  </joint>
  <joint name="SecondarySegmentFinney_Rigid-12" type="fixed">
    <origin rpy="1.5707963267948968 -4.5102810375396984e-17 -4.163336342344337e-17" xyz="-0.0035079199999999843 0.010878390000000024 0.0"/>
    <parent link="SecondarySegmentFinney"/>
    <child link="Secondary-Joint-Cable-SpoolV2"/>
  </joint>
  <joint name="SecondarySegmentFinney_Rigid-13" type="fixed">
    <origin rpy="5.551115123125783e-17 -4.5102810375396984e-17 -4.163336342344337e-17" xyz="0.3078259299999999 0.11527644000000002 -0.06671178000000005"/>
    <parent link="SecondarySegmentFinney"/>
    <child link="Wrist-mount"/>
  </joint>
  <joint name="Openhand1.0_Hand_simplifiedmain-v1_Revolute-21" type="continuous">
    <origin rpy="-1.5707963267948977 1.5165944251834495e-16 -2.9966810540432425" xyz="0.140182 0.011897160000000042 0.07729011000000006"/>
    <parent link="Openhand1.0_Hand_simplifiedmain-v1"/>
    <child link="L1-v1-1"/>
    <axis xyz="-0.0447354719328931 0.242478999999999 0.969124734989744"/>
  </joint>
  <joint name="L1-v1_Revolute-23" type="continuous">
    <origin rpy="1.5707963267948957 -0.14491159954655072 3.141592653589793" xyz="-0.024513608740600077 0.018301310000000015 -0.009115778837997014"/>
    <parent link="L1-v1"/>
    <child link="L2-v1-1"/>
    <axis xyz="0.18421299999999988 0.952507 0.24247899999999997"/>
  </joint>
  <joint name="L1-v1-1_Revolute-24" type="continuous">
    <origin rpy="-1.5707963267948977 -0.1449115995465509 3.141592653589793" xyz="-0.016019316914377236 -0.027475120000000006 0.0027298006878243796"/>
    <parent link="L1-v1-1"/>
    <child link="L2-v1"/>
    <axis xyz="0.18421300000000004 -0.952507 -0.242479"/>
  </joint>
  <joint name="L2-v1_Revolute-25" type="continuous">
    <origin rpy="3.141592653589793 9.244463733058733e-33 5.551115123125783e-17" xyz="0.04472597000000004 0.006437880000000007 0.01487546000000002"/>
    <parent link="L2-v1"/>
    <child link="L3-v1"/>
    <axis xyz="0.18421299999999996 0.952507 0.24247899999999997"/>
  </joint>
  <joint name="L2-v1-1_Revolute-26" type="continuous">
    <origin rpy="-3.141592653589793 -2.775557561562892e-17 1.1102230246251565e-16" xyz="0.04623163000000002 -0.00872086000000003 -0.00705134000000001"/>
    <parent link="L2-v1-1"/>
    <child link="L3-v1-1"/>
    <axis xyz="0.184213 -0.9525069999999999 -0.24247900000000003"/>
  </joint>
  <joint name="Cycloidal_Simplified_for_FEA-1_Revolute-28" type="continuous">
    <origin rpy="-8.632900931077503e-16 1.5777218104420236e-30 0.0" xyz="0.0 0.0 -0.0015000000000000035"/>
    <parent link="Cycloidal_Simplified_for_FEA-1"/>
    <child link="Base_not_rotational"/>
    <axis xyz="-1.5777218104420236e-30 -8.632900931077503e-16 1.0"/>
  </joint>
  <joint name="Base_not_rotational_Rigid-29" type="fixed">
    <origin rpy="1.5707963267948974 -1.2312135847464687e-30 5.551115123125783e-17" xyz="0.0070158500000000856 -0.021756779999999906 -0.07409180000000001"/>
    <parent link="Base_not_rotational"/>
    <child link="Cycloidal_Simplified_for_FEA-2"/>
  </joint>
  <joint name="Cycloidal_Simplified_for_FEA-2_Revolute-30" type="continuous">
    <origin rpy="-1.5707963267948974 -5.551115123125467e-17 3.9443045261050586e-31" xyz="-0.00046036000000000856 0.0 -0.0014276100000000015"/>
    <parent link="Cycloidal_Simplified_for_FEA-2"/>
    <child link="Primary-Segment-Inner"/>
    <axis xyz="0.306905 -0.95174 -4.532335147636025e-16"/>
  </joint>
  <joint name="base_link_Rigid-31" type="fixed">
    <origin rpy="3.141592653589793 0.0 1.5707963267948966" xyz="0.0 0.0 0.025"/>
    <parent link="base_link"/>
    <child link="Cycloidal_Simplified_for_FEA-1"/>
  </joint>
  <joint name="Wrist-mount_Rigid-32" type="fixed">
    <origin rpy="-1.5707963267948966 2.42861286636753e-17 5.551115123125783e-17" xyz="0.012303770000000115 0.003967559999999964 -0.0013695099999998916"/>
    <parent link="Wrist-mount"/>
    <child link="Openhand1.0_Hand_simplifiedmain-v1"/>
  </joint>
  <joint name="Openhand1.0_Hand_simplifiedmain-v1_Revolute-33" type="continuous">
    <origin rpy="-1.5707963267948977 1.5165944251834495e-16 -2.9966810540432425" xyz="0.1584009 0.029608120000000043 0.02155898999999998"/>
    <parent link="Openhand1.0_Hand_simplifiedmain-v1"/>
    <child link="L1-v1"/>
    <axis xyz="-0.0447354719328931 0.242478999999999 0.969124734989744"/>
  </joint>
</robot>
